{
 "cells": [
  {
   "cell_type": "code",
   "execution_count": 1,
   "metadata": {},
   "outputs": [
    {
     "ename": "ImportError",
     "evalue": "Traceback (most recent call last):\n  File \"C:\\Users\\ppragallapati\\DataScience\\lib\\site-packages\\tensorflow\\python\\__init__.py\", line 66, in <module>\n    from tensorflow.python import pywrap_tensorflow\n  File \"C:\\Users\\ppragallapati\\DataScience\\lib\\site-packages\\tensorflow\\python\\pywrap_tensorflow.py\", line 28, in <module>\n    _pywrap_tensorflow = swig_import_helper()\n  File \"C:\\Users\\ppragallapati\\DataScience\\lib\\site-packages\\tensorflow\\python\\pywrap_tensorflow.py\", line 20, in swig_import_helper\n    import _pywrap_tensorflow\nImportError: No module named _pywrap_tensorflow\n\n\nFailed to load the native TensorFlow runtime.\n\nSee https://github.com/tensorflow/tensorflow/blob/master/tensorflow/g3doc/get_started/os_setup.md#import_error\n\nfor some common reasons and solutions.  Include the entire stack trace\nabove this error message when asking for help.",
     "output_type": "error",
     "traceback": [
      "\u001b[1;31m---------------------------------------------------------------------------\u001b[0m",
      "\u001b[1;31mImportError\u001b[0m                               Traceback (most recent call last)",
      "\u001b[1;32m<ipython-input-1-474784adfc80>\u001b[0m in \u001b[0;36m<module>\u001b[1;34m()\u001b[0m\n\u001b[0;32m      1\u001b[0m \u001b[1;32mimport\u001b[0m \u001b[0mnumpy\u001b[0m \u001b[1;32mas\u001b[0m \u001b[0mnp\u001b[0m\u001b[1;33m\u001b[0m\u001b[0m\n\u001b[1;32m----> 2\u001b[1;33m \u001b[1;32mimport\u001b[0m \u001b[0mtensorflow\u001b[0m \u001b[1;32mas\u001b[0m \u001b[0mtf\u001b[0m\u001b[1;33m\u001b[0m\u001b[0m\n\u001b[0m\u001b[0;32m      3\u001b[0m \u001b[1;32mimport\u001b[0m \u001b[0mmatplotlib\u001b[0m\u001b[1;33m.\u001b[0m\u001b[0mpyplot\u001b[0m \u001b[1;32mas\u001b[0m \u001b[0mplt\u001b[0m\u001b[1;33m\u001b[0m\u001b[0m\n",
      "\u001b[1;32mC:\\Users\\ppragallapati\\DataScience\\lib\\site-packages\\tensorflow\\__init__.py\u001b[0m in \u001b[0;36m<module>\u001b[1;34m()\u001b[0m\n\u001b[0;32m     22\u001b[0m \u001b[1;33m\u001b[0m\u001b[0m\n\u001b[0;32m     23\u001b[0m \u001b[1;31m# pylint: disable=wildcard-import\u001b[0m\u001b[1;33m\u001b[0m\u001b[1;33m\u001b[0m\u001b[0m\n\u001b[1;32m---> 24\u001b[1;33m \u001b[1;32mfrom\u001b[0m \u001b[0mtensorflow\u001b[0m\u001b[1;33m.\u001b[0m\u001b[0mpython\u001b[0m \u001b[1;32mimport\u001b[0m \u001b[1;33m*\u001b[0m\u001b[1;33m\u001b[0m\u001b[0m\n\u001b[0m\u001b[0;32m     25\u001b[0m \u001b[1;31m# pylint: enable=wildcard-import\u001b[0m\u001b[1;33m\u001b[0m\u001b[1;33m\u001b[0m\u001b[0m\n\u001b[0;32m     26\u001b[0m \u001b[1;33m\u001b[0m\u001b[0m\n",
      "\u001b[1;32mC:\\Users\\ppragallapati\\DataScience\\lib\\site-packages\\tensorflow\\python\\__init__.py\u001b[0m in \u001b[0;36m<module>\u001b[1;34m()\u001b[0m\n\u001b[0;32m     70\u001b[0m \u001b[1;32mfor\u001b[0m \u001b[0msome\u001b[0m \u001b[0mcommon\u001b[0m \u001b[0mreasons\u001b[0m \u001b[1;32mand\u001b[0m \u001b[0msolutions\u001b[0m\u001b[1;33m.\u001b[0m  \u001b[0mInclude\u001b[0m \u001b[0mthe\u001b[0m \u001b[0mentire\u001b[0m \u001b[0mstack\u001b[0m \u001b[0mtrace\u001b[0m\u001b[1;33m\u001b[0m\u001b[0m\n\u001b[0;32m     71\u001b[0m above this error message when asking for help.\"\"\" % traceback.format_exc()\n\u001b[1;32m---> 72\u001b[1;33m   \u001b[1;32mraise\u001b[0m \u001b[0mImportError\u001b[0m\u001b[1;33m(\u001b[0m\u001b[0mmsg\u001b[0m\u001b[1;33m)\u001b[0m\u001b[1;33m\u001b[0m\u001b[0m\n\u001b[0m\u001b[0;32m     73\u001b[0m \u001b[1;33m\u001b[0m\u001b[0m\n\u001b[0;32m     74\u001b[0m \u001b[1;31m# Protocol buffers\u001b[0m\u001b[1;33m\u001b[0m\u001b[1;33m\u001b[0m\u001b[0m\n",
      "\u001b[1;31mImportError\u001b[0m: Traceback (most recent call last):\n  File \"C:\\Users\\ppragallapati\\DataScience\\lib\\site-packages\\tensorflow\\python\\__init__.py\", line 66, in <module>\n    from tensorflow.python import pywrap_tensorflow\n  File \"C:\\Users\\ppragallapati\\DataScience\\lib\\site-packages\\tensorflow\\python\\pywrap_tensorflow.py\", line 28, in <module>\n    _pywrap_tensorflow = swig_import_helper()\n  File \"C:\\Users\\ppragallapati\\DataScience\\lib\\site-packages\\tensorflow\\python\\pywrap_tensorflow.py\", line 20, in swig_import_helper\n    import _pywrap_tensorflow\nImportError: No module named _pywrap_tensorflow\n\n\nFailed to load the native TensorFlow runtime.\n\nSee https://github.com/tensorflow/tensorflow/blob/master/tensorflow/g3doc/get_started/os_setup.md#import_error\n\nfor some common reasons and solutions.  Include the entire stack trace\nabove this error message when asking for help."
     ]
    }
   ],
   "source": [
    "import numpy as np\n",
    "import tensorflow as tf\n",
    "import matplotlib.pyplot as plt\n"
   ]
  },
  {
   "cell_type": "code",
   "execution_count": null,
   "metadata": {},
   "outputs": [],
   "source": []
  }
 ],
 "metadata": {
  "kernelspec": {
   "display_name": "Python 2",
   "language": "python",
   "name": "python2"
  },
  "language_info": {
   "codemirror_mode": {
    "name": "ipython",
    "version": 2
   },
   "file_extension": ".py",
   "mimetype": "text/x-python",
   "name": "python",
   "nbconvert_exporter": "python",
   "pygments_lexer": "ipython2",
   "version": "2.7.15"
  }
 },
 "nbformat": 4,
 "nbformat_minor": 2
}
